Workbook

Sheet BankPresentation BS
A1: Bravado Spice LLC
A2: Comparative Balance Sheets
C4: December 31,
C5: 2022 | D5: 2021
A6: Assets
A7: Current Assets
B8: Cash | C8: ='Balance Sheet'!B15 -> 49122.45 | D8: ='Balance Sheet'!C15 -> 97922.05
B9: Accounts receivable | C9: ='Balance Sheet'!B18 -> 176485.4 | D9: ='Balance Sheet'!C18 -> 158704.13
B10: Inventory | C10: ='Balance Sheet'!B27 -> 390898.41 | D10: ='Balance Sheet'!C27 -> 313525.6
B11: Other | C11: ='Balance Sheet'!B20+'Balance Sheet'!B29+'Balance Sheet'!B30+'Balance Sheet'!B31 -> 40490.52 | D11: ='Balance Sheet'!C29+'Balance Sheet'!C31 -> 27482.35
B12: Total current assets | C12: =SUM(C8:C11) -> 656996.78 | D12: =SUM(D8:D11) -> 597634.13
A14: Property & Equipment
B15: Machinery | C15: ='Balance Sheet'!B35 -> 14069.56 | D15: ='Balance Sheet'!C35 -> 14069.56
B16: Vehicles | C16: ='Balance Sheet'!B36+'Balance Sheet'!B37+'Balance Sheet'!B38 -> 85655.92 | D16: ='Balance Sheet'!C36+'Balance Sheet'!C37+'Balance Sheet'!C38 -> 85655.92
B17: Accumulated depreciation | C17: ='Balance Sheet'!B39 -> -99725.48 | D17: ='Balance Sheet'!C39 -> -99725.48
B18: Total property & equipment | C18: =SUM(C15:C17) -> 0
A20: Other Assets | C20: ='Balance Sheet'!B43 -> 8799.4 | D20: ='Balance Sheet'!C42 -> 8799.4
B21: Total assets | C21: =C12+C18+C20 -> 665796.18 | D21: =D12+D18+D20 -> 606433.53
A23: Liabilities and Equity
A24: Current Liabilities
B25: Accounts payable | C25: ='Balance Sheet'!B50 -> 109115.57 | D25: ='Balance Sheet'!C50 -> 190713.27
B26: Credit cards | C26: ='Balance Sheet'!B62 -> 115930.39 | D26: ='Balance Sheet'!C62 -> 66219.9
B27: LOC | C27: ='Balance Sheet'!B69 -> 113361.74 | D27: ='Balance Sheet'!C69 -> 0
B28: Other | C28: ='Balance Sheet'!B71+'Balance Sheet'!B73 -> 9714 | D28: ='Balance Sheet'!C71+'Balance Sheet'!C73 -> 15330.8
B29: Total current liabilities | C29: =SUM(C25:C28) -> 348121.7 | D29: =SUM(D25:D28) -> 272263.97
A31: Long-Term Debt | C31: ='Balance Sheet'!B85 -> 152599.61 | D31: ='Balance Sheet'!C85 -> 105749.99
A33: Equity
B34: Members interests | C34: ='Balance Sheet'!B88+'Balance Sheet'!B90+'Balance Sheet'!B91 -> -57246.07 | D34: ='Balance Sheet'!C88+'Balance Sheet'!C90+'Balance Sheet'!C91 -> -14443.04
B35: Retained earnings | C35: ='Balance Sheet'!B89+'Balance Sheet'!B92 -> 222320.94 | D35: ='Balance Sheet'!C89+'Balance Sheet'!C92 -> 242862.61
B36: Total equity | C36: =SUM(C34:C35) -> 165074.87 | D36: =SUM(D34:D35) -> 228419.57
B37: Total liabilities and equity | C37: =C29+C31+C36 -> 665796.18 | D37: =D29+D31+D36 -> 606433.53

Sheet Bank Presentation IS
A1: Bravado Spice LLC
A2: Comparative Balance Sheets
C4: ACTUAL | G4: PRE_CLOSING | I4: FORECAST
C5: Year Ended December 31,
C6: 2020 | E6: 2021 | G6: 2022 | I6: 2023
A8: Sales | C8: ='2024 Monthly'!E14 -> 2169255.1 | D8: =C8/C$8 -> 1 | E8: ='2024 Monthly'!G14 -> 2201897 | F8: =E8/E$8 -> 1 | G8: ='2024 Monthly'!M14 -> 2325993.4 | H8: =G8/G$8 -> 1 | I8: ='2024 Monthly'!T14 -> 3130981.5 | J8: =I8/I$8 -> 1
A10: Cost of Goods Sold | C10: ='2024 Monthly'!E23 -> 1214762.6 | D10: =C10/C$8 -> 0.55999065 | E10: ='2024 Monthly'!G23 -> 1468052.7 | F10: =E10/E$8 -> 0.66672179 | G10: ='2024 Monthly'!M23 -> 1311764.4 | H10: =G10/G$8 -> 0.56395879 | I10: ='2024 Monthly'!T23 -> 1732402.9 | J10: =I10/I$8 -> 0.55330987
A11: Gross Margin | C11: =C8-C10 -> 954492.55 | D11: =C11/C$8 -> 0.44000935 | E11: =E8-E10 -> 733844.3 | F11: =E11/E$8 -> 0.33327821 | G11: =G8-G10 -> 1014229 | H11: =G11/G$8 -> 0.43604121 | I11: =I8-I10 -> 1398578.5 | J11: =I11/I$8 -> 0.44669013
A12: Selling, General & Administrative Expenses
B13: Compensation | C13: ='2024 Monthly'!E42 -> 302985.14 | D13: =C13/C$8 -> 0.13967243 | E13: ='2024 Monthly'!G42 -> 444817.26 | F13: =E13/E$8 -> 0.20201547 | G13: ='2024 Monthly'!M42 -> 550362.48 | H13: =G13/G$8 -> 0.23661395 | I13: ='2024 Monthly'!T42 -> 653489.76 | J13: =I13/I$8 -> 0.20871722
B14: Marketing & advertising | C14: ='2024 Monthly'!E43 -> 126166.54 | D14: =C14/C$8 -> 0.058161227 | E14: ='2024 Monthly'!G43 -> 153428.37 | F14: =E14/E$8 -> 0.069680085 | G14: ='2024 Monthly'!M43 -> 182977.57 | H14: =G14/G$8 -> 0.07866642 | I14: ='2024 Monthly'!T43 -> 215700 | J14: =I14/I$8 -> 0.068892135
B15: Rent | C15: ='2024 Monthly'!E51 -> 32084.48 | D15: =C15/C$8 -> 0.014790552 | E15: ='2024 Monthly'!G51 -> 84207.42 | F15: =E15/E$8 -> 0.038243124 | G15: ='2024 Monthly'!M51 -> 109405.43 | H15: =G15/G$8 -> 0.047036003 | I15: ='2024 Monthly'!T51 -> 114000 | J15: =I15/I$8 -> 0.036410308
B16: Office expenses | C16: ='2024 Monthly'!E52 -> 28881.79 | D16: =C16/C$8 -> 0.013314151 | E16: ='2024 Monthly'!G52 -> 62978.55 | F16: =E16/E$8 -> 0.028601951 | G16: ='2024 Monthly'!M52 -> 65098.44 | H16: =G16/G$8 -> 0.027987371 | I16: ='2024 Monthly'!T52 -> 60000 | J16: =I16/I$8 -> 0.01916332
B17: Professional fees | C17: ='2024 Monthly'!E59 -> 14641.91 | D17: =C17/C$8 -> 0.0067497408 | E17: ='2024 Monthly'!G59 -> 25989.68 | F17: =E17/E$8 -> 0.011803313 | G17: ='2024 Monthly'!M59 -> 19266.98 | H17: =G17/G$8 -> 0.0082833341 | I17: ='2024 Monthly'!T59 -> 41766.98 | J17: =I17/I$8 -> 0.0133399
B18: Travel | C18: ='2024 Monthly'!E53 -> 6913.83 | D18: =C18/C$8 -> 0.0031871908 | E18: ='2024 Monthly'!G53 -> 9268.26 | F18: =E18/E$8 -> 0.0042092159 | G18: ='2024 Monthly'!M53 -> 23883.94 | H18: =G18/G$8 -> 0.010268275 | I18: ='2024 Monthly'!T53 -> 23883.94 | J18: =I18/I$8 -> 0.0076282598
B19: Software dues & subscriptions | C19: ='2024 Monthly'!E54 -> 9832.89 | D19: =C19/C$8 -> 0.0045328416 | E19: ='2024 Monthly'!G54 -> 13230.97 | F19: =E19/E$8 -> 0.0060088959 | G19: ='2024 Monthly'!M54 -> 20485.7 | H19: =G19/G$8 -> 0.0088072908 | I19: ='2024 Monthly'!T54 -> 20485.7 | J19: =I19/I$8 -> 0.0065429004
B20: Insurance | C20: ='2024 Monthly'!E55 -> 9618.2 | D20: =C20/C$8 -> 0.0044338722 | E20: ='2024 Monthly'!G55 -> 19428.15 | F20: =E20/E$8 -> 0.0088233691 | G20: ='2024 Monthly'!M55 -> 16312.52 | H20: =G20/G$8 -> 0.0070131413 | I20: ='2024 Monthly'!T55 -> 17128.146 | J20: =I20/I$8 -> 0.0054705357
B21: Utilities | C21: ='2024 Monthly'!E56 -> 4766.11 | D21: =C21/C$8 -> 0.0021971182 | E21: ='2024 Monthly'!G56 -> 12331.72 | F21: =E21/E$8 -> 0.0056004981 | G21: ='2024 Monthly'!M56 -> 13550.21 | H21: =G21/G$8 -> 0.0058255583 | I21: ='2024 Monthly'!T56 -> 13550.21 | J21: =I21/I$8 -> 0.0043277835
B22: Repairs & maintenance | C22: ='2024 Monthly'!E60 -> 3200.57 | D22: =C22/C$8 -> 0.0014754235 | E22: ='2024 Monthly'!G60 -> 8234.48 | F22: =E22/E$8 -> 0.0037397208 | G22: ='2024 Monthly'!M60 -> 11019.92 | H22: =G22/G$8 -> 0.0047377263 | I22: ='2024 Monthly'!T60 -> 11019.92 | J22: =I22/I$8 -> 0.0035196376
B23: Taxes & licenses | C23: ='2024 Monthly'!E61 -> 3042.38 | D23: =C23/C$8 -> 0.0014024998 | E23: ='2024 Monthly'!G61 -> 22007.56 | F23: =E23/E$8 -> 0.0099948181 | G23: ='2024 Monthly'!M61 -> 9261.62 | H23: =G23/G$8 -> 0.0039817912 | I23: ='2024 Monthly'!T61 -> 9901.794 | J23: =I23/I$8 -> 0.0031625208
B24: Reimbursements | C24: ='2024 Monthly'!E62 -> 0 | D24: =C24/C$8 -> 0 | E24: ='2024 Monthly'!G62 -> 32.44 | F24: =E24/E$8 -> 1.4732751e-05 | G24: ='2024 Monthly'!M62 -> 3653.13 | H24: =G24/G$8 -> 0.0015705677 | I24: ='2024 Monthly'!T62 -> 3653.13 | J24: =I24/I$8 -> 0.0011667683
B25: Bad debts | C25: ='2024 Monthly'!E67 -> 6737.83 | D25: =C25/C$8 -> 0.0031060569 | E25: ='2024 Monthly'!G67 -> 0 | F25: =E25/E$8 -> 0 | G25: ='2024 Monthly'!M67 -> 0 | H25: =G25/G$8 -> 0 | I25: ='2024 Monthly'!T67 -> 2000 | J25: =I25/I$8 -> 0.00063877733
B26: Miscellaneous | C26: ='2024 Monthly'!E68 -> 4773.89 | D26: =C26/C$8 -> 0.0022007047 | E26: ='2024 Monthly'!G68 -> 1597.54 | F26: =E26/E$8 -> 0.00072552894 | G26: ='2024 Monthly'!M68 -> 1085.26 | H26: =G26/G$8 -> 0.00046657915 | I26: ='2024 Monthly'!T68 -> 10000 | J26: =I26/I$8 -> 0.0031938867
B27: Total S, G & A expenses | C27: =SUM(C13:C26) -> 553645.56 | D27: =C27/C$8 -> 0.25522381 | E27: =SUM(E13:E26) -> 857552.4 | F27: =E27/E$8 -> 0.38946072 | G27: =SUM(G13:G26) -> 1026363.2 | H27: =G27/G$8 -> 0.44125801 | I27: =SUM(I13:I26) -> 1196579.6 | J27: =I27/I$8 -> 0.38217396
A28: EBITDA | C28: =C11-C27 -> 400846.99 | D28: =C28/C$8 -> 0.18478554 | E28: =E11-E27 -> -123708.1 | F28: =E28/E$8 -> -0.05618251 | G28: =G11-G27 -> -12134.23 | H28: =G28/G$8 -> -0.0052167948 | I28: =I11-I27 -> 201998.95 | J28: =I28/I$8 -> 0.064516175
A30: Other Income/Expenses
B31: Non-operating | C31: ='2024 Monthly'!#REF! -> #REF! | D31: =C31/C$8 -> #REF! | E31: ='2024 Monthly'!#REF! -> #REF! | F31: =E31/E$8 -> #REF! | G31: ='2024 Monthly'!#REF! -> #REF! | H31: =G31/G$8 -> #REF! | I31: ='2024 Monthly'!#REF! -> #REF! | J31: =I31/I$8 -> #REF!
B32: Interest & fees | C32: ='2024 Monthly'!E82 -> 2481.65 | D32: =C32/C$8 -> 0.0011440102 | E32: ='2024 Monthly'!G82 -> 8155.74 | F32: =E32/E$8 -> 0.0037039607 | G32: ='2024 Monthly'!M82 -> 33783.04 | H32: =G32/G$8 -> 0.014524134 | I32: ='2024 Monthly'!T82 -> 30404.736 | J32: =I32/I$8 -> 0.0097109281
B33: Depreciation | C33: ='2024 Monthly'!E86 -> 0 | D33: =C33/C$8 -> 0 | E33: ='2024 Monthly'!G86 -> 0 | F33: =E33/E$8 -> 0 | G33: ='2024 Monthly'!M86 -> 0 | H33: =G33/G$8 -> 0 | I33: ='2024 Monthly'!T86 -> 0 | J33: =I33/I$8 -> 0
A34: Net Income(Loss) | C34: =C28-C31-C32-C33 -> #REF! | D34: =C34/C$8 -> #REF! | E34: =E28-E31-E32-E33 -> #REF! | F34: =E34/E$8 -> #REF! | G34: =G28-G31-G32-G33 -> #REF! | H34: =G34/G$8 -> #REF! | I34: =I28-I31-I32-I33 -> #REF! | J34: =I34/I$8 -> #REF!

Sheet IS v PY
A1: Bravado Spice
A2: Income Statement
C3: Four Months Ended April 30,
C4: 2023 | E4: 2022
A5: Sales
B6: Retail | C6: 72718 | D6: =C6/C$10 -> 0.1043872 | E6: 92509 | F6: =E6/E$10 -> 0.12327433
B7: Online/Amazon | C7: =65107+46128 -> 111235 | D7: =C7/C$10 -> 0.15967862 | E7: =62366+75286 -> 137652 | F7: =E7/E$10 -> 0.18343034
B8: Distributor | C8: 204747 | D8: =C8/C$10 -> 0.29391575 | E8: 169379 | F8: =E8/E$10 -> 0.22570866
B9: Franchise | C9: 307918 | D9: =C9/C$10 -> 0.44201844 | E9: 350892 | F9: =E9/E$10 -> 0.46758667
B10: Total sales | C10: =SUM(C6:C9) -> 696618 | D10: =C10/C$10 -> 1 | E10: =SUM(E6:E9) -> 750432 | F10: =E10/E$10 -> 1
A11: Cost of Sales | C11: 372326 | D11: =C11/C$10 -> 0.53447657 | E11: 439232 | F11: =E11/E$10 -> 0.58530553
A12: Gross Margin | C12: =C10-C11 -> 324292 | D12: =C12/C$10 -> 0.46552343 | E12: =E10-E11 -> 311200 | F12: =E12/E$10 -> 0.41469447
A14: Selling, General & Administrative
B15: Compensation
B16: Salaries & wages | C16: 129607 | D16: =C16/C$10 -> 0.18605175 | E16: 115382 | F16: =E16/E$10 -> 0.1537541
B17: Contract labor | C17: 34626 | D17: =C17/C$10 -> 0.049705865 | E17: 21259 | F17: =E17/E$10 -> 0.028329016
B18: Payroll taxes | C18: 10032 | D18: =C18/C$10 -> 0.014401006 | E18: 9035 | F18: =E18/E$10 -> 0.012039732
B19: Employee benefits | C19: 4147 | D19: =C19/C$10 -> 0.0059530474 | E19: 6169 | F19: =E19/E$10 -> 0.0082205983
B20: Total compensation | C20: =SUM(C16:C19) -> 178412 | D20: =C20/C$10 -> 0.25611167 | E20: =SUM(E16:E19) -> 151845 | F20: =E20/E$10 -> 0.20234345
B21: Marketing & advertising | C21: 58892 | D21: =C21/C$10 -> 0.084539877 | E21: 46619 | F21: =E21/E$10 -> 0.062122884
B22: Rent | C22: 46647 | D22: =C22/C$10 -> 0.066962094 | E22: 34822 | F22: =E22/E$10 -> 0.046402605
B23: Other G&A | C23: =SUM(C24:C35) -> 81756 | D23: =C23/C$10 -> 0.11736131 | E23: =SUM(E24:E35) -> 56628 | F23: =E23/E$10 -> 0.075460535
B24: Office expenses | C24: 17745 | D24: =C24/C$10 -> 0.025473071 | E24: 14657 | F24: =E24/E$10 -> 0.019531417
B25: Travel | C25: 11836 | D25: =C25/C$10 -> 0.016990661 | E25: 9654 | F25: =E25/E$10 -> 0.01286459
B26: Dues & subscriptions | C26: 10026 | D26: =C26/C$10 -> 0.014392393 | E26: 5512 | F26: =E26/E$10 -> 0.0073451026
B27: Insurance | C27: 7765 | D27: =C27/C$10 -> 0.011146712 | E27: 6891 | F27: =E27/E$10 -> 0.0091827108
B28: Utilities | C28: 5418 | D28: =C28/C$10 -> 0.0077775768 | E28: 4528 | F28: =E28/E$10 -> 0.0060338578
B29: Professional fees | C29: 13153 | D29: =C29/C$10 -> 0.018881223 | E29: 2789 | F29: =E29/E$10 -> 0.0037165259
B30: Repairs & maintenance | C30: 4291 | D30: =C30/C$10 -> 0.0061597604 | E30: 6105 | F30: =E30/E$10 -> 0.0081353141
B31: Taxes & licenses | C31: 849 | D31: =C31/C$10 -> 0.0012187454 | E31: 2320 | F31: =E31/E$10 -> 0.0030915526
B32: Reimbursements | C32: 1453 | D32: =C32/C$10 -> 0.0020857916 | E32: 1029 | F32: =E32/E$10 -> 0.0013712102
B33: Bank fees | C33: 9042 | D33: =C33/C$10 -> 0.012979854 | E33: 2959 | F33: =E33/E$10 -> 0.0039430621
B34: Bad debts | C34: 0 | D34: =C34/C$10 -> 0 | E34: 0 | F34: =E34/E$10 -> 0
B35: Miscellaneous | C35: 178 | D35: =C35/C$10 -> 0.00025552024 | E35: 184 | F35: =E35/E$10 -> 0.0002451921
B36: Total SG&A | C36: =SUM(C20:C35)-C23 -> 365707 | D36: =C36/C$10 -> 0.52497495 | E36: =SUM(E20:E35)-E23 -> 289914 | F36: =E36/E$10 -> 0.38632947
A37: EBITDA | C37: =C12-C36 -> -41415 | D37: =C37/C$10 -> -0.059451521 | E37: =E12-E36 -> 21286 | F37: =E37/E$10 -> 0.028364995
A38: Other Income/Expenses
B39: Nonoperating income/expenses | D39: =C39/C$10 -> 0 | F39: =E39/E$10 -> 0
B40: Interest & CC fees | C40: 22470 | D40: =C40/C$10 -> 0.032255842 | E40: 2092 | F40: =E40/E$10 -> 0.0027877276
B41: Depreciation | C41: =QB!F131 -> 0 | D41: =C41/C$10 -> 0 | F41: =E41/E$10 -> 0
...

Sheet Financial Trend.Budget
A1: Bravado Spice
A2: Forecast 2024-2025 | AJ2: 2024 by Month | AZ2: 2025 by Month
K3: 2023 Forecast (Original) | R3: 2023 Forecast (Original)
A4: (assuming Investment November, 2024) | K4: 2023 | R4: 2024 | Z4: 2025 | AJ4: Actual | AR4: Budget | AZ4: Budget
C5: 2019 | E5: 2020 | G5: 2021 | I5: 2022 | K5: Q1 | L5: Q2 | M5: Q3 | N5: Q4 | O5: 2023 | R5: Q1 | S5: Q2 | T5: Q3 | U5: Q4 | V5: 2024 | X5: Notes | Z5: Q1 | AA5: Q2 | AB5: Q3 | AC5: Q4 | AD5: 2025 | AF5: Q3 Actual | AG5: Oct | AH5: Nov | AI5: Dec | AJ5: Jan | AK5: Feb | AL5: Mar | AM5: Apr | AN5: May | AO5: June | AP5: July | AQ5: Aug | AR5: Sept | AS5: Oct | AT5: Nov | AU5: Dec | AV5: 2024 Total | AX5: Assumptions | AZ5: Jan | BA5: Feb | BB5: Mar | BC5: Apr | BD5: May | BE5: June | BF5: July | BG5: Aug | BH5: Sept | BI5: Oct | BJ5: Nov | BK5: Dec | BL5: 2025 Total
A6: Sales
B7: Retail | AV7: =SUM(AJ7:AU7) -> 0 | AW7: =AV7/AV$15 -> 0 | BL7: =SUM(AZ7:BK7) -> 0
B8: Online/Amazon | AV8: =SUM(AJ8:AU8) -> 0 | AW8: =AV8/AV$15 -> 0 | BL8: =SUM(AZ8:BK8) -> 0
B9: Less Amazon netting | AV9: =SUM(AJ9:AU9) -> 0 | AW9: =AV9/AV$15 -> 0 | BL9: =SUM(AZ9:BK9) -> 0
B10: Distributor | AV10: =SUM(AJ10:AU10) -> 0 | AW10: =AV10/AV$15 -> 0 | BL10: =SUM(AZ10:BK10) -> 0
B11: Franchise | AV11: =SUM(AJ11:AU11) -> 0 | AW11: =AV11/AV$15 -> 0 | BL11: =SUM(AZ11:BK11) -> 0
B12: Total hot sauce | C12: =QB!F20+QB!F30+QB!F33+QB!F34+QB!F40 -> 1176162.1 | E12: =QB!K20+QB!K30+QB!K33+QB!K34+QB!K40 -> 1985300.7 | G12: =QB!P20+QB!P30+QB!P33+QB!P34+QB!P40 -> 1946199.2
B13: Mixers & seasonings | C13: =QB!F24+QB!F29 -> 98761.52 | E13: =QB!K24+QB!K29 -> 182871.54 | G13: =QB!P24+QB!P29 -> 249354.5
B14: Other | C14: =QB!F42+QB!F43+QB!F44 -> 5945.28 | E14: =QB!K42+QB!K43+QB!K44 -> 1082.89 | G14: =QB!P42+QB!P43+QB!P44 -> 6343.26
A15: Sales | C15: =SUM(C12:C14) -> 1280868.9 | D15: =C15/C$15 -> 1 | E15: =SUM(E12:E14) -> 2169255.1 | F15: =E15/E$15 -> 1 | G15: =SUM(G12:G14) -> 2201897 | H15: =G15/G$15 -> 1 | I15: 2321440 | J15: =I15/I$15 -> 1 | K15: 570041 | L15: 405174 | M15: 347143 | N15: 432361 | O15: =SUM(K15:N15) -> 1754719 | P15: =O15/O$15 -> 1 | R15: =SUM(AJ15:AL15) -> 232955 | S15: =SUM(AM15:AO15) -> 218307 | T15: =SUM(AP15:AR15) -> 177640 | U15: =SUM(AS15:AU15) -> 320000 | V15: =SUM(R15:U15) -> 948902 | W15: =V15/V$15 -> 1 | Z15: =SUM(AZ15:BB15) -> 270000 | AA15: =SUM(BC15:BE15) -> 350000 | AB15: =SUM(BF15:BH15) -> 390000 | AC15: =SUM(BI15:BK15) -> 485000 | AD15: =SUM(Z15:AC15) -> 1495000 | AF15: 347143 | AG15: 155912 | AH15: 147384 | AI15: 129065 | AJ15: 97342 | AK15: 69706 | AL15: 65907 | AM15: 58908 | AN15: 77566 | AO15: 81833 | AP15: 64514 | AQ15: 34126 | AR15: 79000 | AS15: 120000 | AT15: 100000 | AU15: 100000 | AV15: =SUM(AJ15:AU15) -> 948902 | AW15: =AV15/AV$15 -> 1 | AX15: Per Jer | AZ15: 100000 | BA15: 80000 | BB15: 90000 | BC15: 110000 | BD15: 120000 | BE15: 120000 | BF15: 120000 | BG15: 130000 | BH15: 140000 | BI15: 180000 | BJ15: 180000 | BK15: 125000 | BL15: =SUM(AZ15:BK15) -> 1495000 | BM15: =BL15/BL$15 -> 1
A16: Cost of Sales
B17: Co-Packer & ingredients | C17: =QB!F47+QB!F48+QB!F50+QB!F51 -> 497738.93 | D17: =C17/C$15 -> 0.38859476 | E17: 725353 | F17: =E17/E$15 -> 0.33437883 | G17: =QB!P47+QB!P48+QB!P50+QB!P51 -> 943998.9 | H17: =G17/G$15 -> 0.42872073 | I17: 1012654 | J17: =I17/I$15 -> 0.43621804 | K17: 342783 | L17: 213990 | M17: 225540 | N17: 184128 | O17: =SUM(K17:N17) -> 966441 | P17: =O17/O$15 -> 0.55076682 | R17: =SUM(AJ17:AL17) -> 101494 | S17: =SUM(AM17:AO17) -> 125394 | T17: =SUM(AP17:AR17) -> 63093 | U17: =SUM(AS17:AU17) -> 134400 | V17: =SUM(R17:U17) -> 424381 | W17: =V17/V$15 -> 0.44723375 | Z17: =SUM(AZ17:BB17) -> 113400 | AA17: =SUM(BC17:BE17) -> 147000 | AB17: =SUM(BF17:BH17) -> 163800 | AC17: =SUM(BI17:BK17) -> 203700 | AD17: =SUM(Z17:AC17) -> 627900 | AF17: 199547 | AG17: 51354 | AH17: 56556 | AI17: 54070 | AJ17: 40909 | AK17: 27875 | AL17: 32710 | AM17: 44532 | AN17: 47512 | AO17: 33350 | AP17: 21398 | AQ17: 11321 | AR17: 30374 | AS17: =AS15*0.42 -> 50400 | AT17: =AT15*0.42 -> 42000 | AU17: =AU15*0.42 -> 42000 | AV17: =SUM(AJ17:AU17) -> 424381 | AW17: =AV17/AV$15 -> 0.44723375 | AX17: 45% of sales starting June | AZ17: =AZ15*0.42 -> 42000 | BA17: =BA15*0.42 -> 33600 | BB17: =BB15*0.42 -> 37800 | BC17: =BC15*0.42 -> 46200 | BD17: =BD15*0.42 -> 50400 | BE17: =BE15*0.42 -> 50400 | BF17: =BF15*0.42 -> 50400 | BG17: =BG15*0.42 -> 54600 | ... BK17: =BK15*0.42 -> 52500 | BL17: =SUM(AZ17:BK17) -> 627900 | BM17: =BL17/BL$15 -> 0.42
B18: Shipping & delivery | C18: =QB!F49 -> 115308.88 | D18: =C18/C$15 -> 0.090023954 | E18: =QB!K49 -> 198278.67 | F18: =E18/E$15 -> 0.091404034 | G18: =QB!P49 -> 268052.97 | H18: =G18/G$15 -> 0.12173729 | I18: 214975 | J18: =I18/I$15 -> 0.092604159 | K18: 46962 | L18: 32407 | M18: 27976 | N18: 27158 | O18: =SUM(K18:N18) -> 134503 | P18: =O18/O$15 -> 0.076652159 | R18: =SUM(AJ18:AL18) -> 18015 | S18: =SUM(AM18:AO18) -> 12763 | T18: =SUM(AP18:AR18) -> 11467 | U18: =SUM(AS18:AU18) -> 19200 | V18: =SUM(R18:U18) -> 61445 | W18: =V18/V$15 -> 0.064753789 | Z18: =SUM(AZ18:BB18) -> 16200 | AA18: =SUM(BC18:BE18) -> 21000 | AB18: =SUM(BF18:BH18) -> 23400 | AC18: =SUM(BI18:BK18) -> 29100 | AD18: =SUM(Z18:AC18) -> 89700 | AF18: 27976 | AG18: 8573 | AH18: 10446 | AI18: 8139 | AJ18: 8646 | AK18: 5159 | AL18: 4210 | AM18: 4062 | AN18: 5030 | AO18: 3671 | AP18: 4688 | AQ18: 3279 | AR18: 3500 | AS18: =0.06*AS15 -> 7200 | AT18: =0.06*AT15 -> 6000 | AU18: =0.06*AU15 -> 6000 | AV18: =SUM(AJ18:AU18) -> 61445 | AW18: =AV18/AV$15 -> 0.064753789 | AX18: 7% of sales | AZ18: =0.06*AZ15 -> 6000 | BA18: =0.06*BA15 -> 4800 | BB18: =0.06*BB15 -> 5400 | BC18: =0.06*BC15 -> 6600 | BD18: =0.06*BD15 -> 7200 | BE18: =0.06*BE15 -> 7200 | BF18: =0.06*BF15 -> 7200 | BG18: =0.06*BG15 -> 7800 | ... BK18: =0.06*BK15 -> 7500 | BL18: =SUM(AZ18:BK18) -> 89700 | BM18: =BL18/BL$15 -> 0.06
B19: Inventory adjustment | I19: -100 | J19: =I19/I$15 -> -4.3076711e-05 | O19: =SUM(K19:N19) -> 0 | R19: =SUM(AJ19:AL19) -> 6240 | S19: =SUM(AM19:AO19) -> 3848 | T19: =SUM(AP19:AR19) -> 2171 | U19: =SUM(AS19:AU19) -> 0 | V19: =SUM(R19:U19) -> 12259 | W19: =V19/V$15 -> 0.012919142 | Z19: =SUM(AZ19:BB19) -> 0 | AA19: =SUM(BC19:BE19) -> 0 | AB19: =SUM(BF19:BH19) -> 0 | AC19: =SUM(BI19:BK19) -> 0 | AD19: =SUM(Z19:AC19) -> 0 | AJ19: 6900 | AK19: -2315 | AL19: 1655 | AM19: 2783 | AN19: 696 | AO19: 369 | AP19: 1326 | AQ19: 845 | AV19: =SUM(AJ19:AU19) -> 12259 | AW19: =AV19/AV$15 -> 0.012919142 | BL19: =SUM(AZ19:BK19) -> 0 | BM19: =BL19/BL$15 -> 0
B20: Materials | C20: =QB!F52 -> 128054.04 | D20: =C20/C$15 -> 0.099974356 | E20: =QB!K52 -> 194413.35 | F20: =E20/E$15 -> 0.089622169 | G20: =QB!P52 -> 179567.31 | H20: =G20/G$15 -> 0.081551185 | J20: =I20/I$15 -> 0 | K20: =SUM(I20:J20) -> 0 | L20: =SUM(I20:K20) -> 0 | M20: =SUM(J20:L20) -> 0 | N20: =SUM(K20:M20) -> 0 | O20: =SUM(K20:N20) -> 0 | P20: =O20/O$15 -> 0 | R20: =SUM(AJ20:AL20) -> 0 | S20: =SUM(AM20:AO20) -> 0 | T20: =SUM(AP20:AR20) -> 0 | U20: =SUM(AS20:AU20) -> 0 | V20: =SUM(R20:U20) -> 0 | W20: =V20/V$15 -> 0 | Z20: =SUM(AZ20:BB20) -> 0 | AA20: =SUM(BC20:BE20) -> 0 | AB20: =SUM(BF20:BH20) -> 0 | AC20: =SUM(BI20:BK20) -> 0 | AD20: =SUM(Z20:AC20) -> 0 | AV20: =SUM(AJ20:AU20) -> 0 | AW20: =AV20/AV$15 -> 0 | BL20: =SUM(AZ20:BK20) -> 0 | BM20: =BL20/BL$15 -> 0
B21: KeHe slotting fees | O21: =SUM(K21:N21) -> 0 | R21: =SUM(AJ21:AL21) -> 0 | S21: =SUM(AM21:AO21) -> 0 | T21: =SUM(AP21:AR21) -> 0 | U21: =SUM(AS21:AU21) -> 0 | V21: =SUM(R21:U21) -> 0 | W21: =V21/V$15 -> 0 | Z21: =SUM(AZ21:BB21) -> 0 | AA21: =SUM(BC21:BE21) -> 0 | AB21: =SUM(BF21:BH21) -> 0 | AC21: =SUM(BI21:BK21) -> 0 | AD21: =SUM(Z21:AC21) -> 0 | AV21: =SUM(AJ21:AU21) -> 0 | AW21: =AV21/AV$15 -> 0 | BL21: =SUM(AZ21:BK21) -> 0 | BM21: =BL21/BL$15 -> 0
B22: Swell/other discounts | C22: 25822 | D22: =C22/C$15 -> 0.020159753 | E22: 62660 | F22: =E22/E$15 -> 0.028885491 | I22: 82476 | J22: =I22/I$15 -> 0.035527948 | K22: 18624 | L22: 15910 | M22: 46676 | N22: 34766 | O22: =SUM(K22:N22) -> 115976 | P22: =O22/O$15 -> 0.066093773 | R22: =SUM(AJ22:AL22) -> 42841 | S22: =SUM(AM22:AO22) -> 11937 | T22: =SUM(AP22:AR22) -> 13016 | U22: =SUM(AS22:AU22) -> 19200 | V22: =SUM(R22:U22) -> 86994 | W22: =V22/V$15 -> 0.091678593 | Z22: =SUM(AZ22:BB22) -> 16200 | AA22: =SUM(BC22:BE22) -> 17500 | AB22: =SUM(BF22:BH22) -> 19500 | AC22: =SUM(BI22:BK22) -> 24250 | AD22: =SUM(Z22:AC22) -> 77450 | AF22: 52288 | AG22: 20454 | AH22: 12986 | AI22: 2493 | AJ22: 19221 | AK22: 18623 | AL22: 4997 | AM22: 7371 | AN22: 2440 | AO22: 2126 | AP22: 5444 | AQ22: 3298 | AR22: 4274 | AS22: =AS15*0.06 -> 7200 | AT22: =AT15*0.06 -> 6000 | AU22: =AU15*0.06 -> 6000 | AV22: =SUM(AJ22:AU22) -> 86994 | AW22: =AV22/AV$15 -> 0.091678593 | AX22: 8% of sales, bump in June promo, 6% last few mos | AZ22: =AZ15*0.06 -> 6000 | BA22: =BA15*0.06 -> 4800 | BB22: =BB15*0.06 -> 5400 | BC22: =BC15*0.05 -> 5500 | BD22: =BD15*0.05 -> 6000 | BE22: =BE15*0.05 -> 6000 | BF22: =BF15*0.05 -> 6000 | BG22: =BG15*0.05 -> 6500 | BH22: =BH15*0.05 -> 7000 | BI22: =BI15*0.05 -> 9000 | BJ22: =BJ15*0.05 -> 9000 | BK22: =BK15*0.05 -> 6250 | BL22: =SUM(AZ22:BK22) -> 77450 | BM22: =BL22/BL$15 -> 0.05180602
B23: Other | D23: =C23/C$15 -> 0 | E23: 33331 | F23: =E23/E$15 -> 0.015365182 | G23: =QB!P53+QB!P54+QB!P55+QB!P56+QB!P57+QB!P58+QB!P59+QB!P60+QB!P61+QB!P62+QB!P64 -> 76433.53 | H23: =G23/G$15 -> 0.034712582 | I23: 1566 | J23: =I23/I$15 -> 0.00067458129 | K23: 7237 | L23: 1331 | M23: 9057 | N23: 4257 | O23: =SUM(K23:N23) -> 21882 | P23: =O23/O$15 -> 0.012470373 | R23: =SUM(AJ23:AL23) -> 7098 | S23: =SUM(AM23:AO23) -> 6573 | T23: =SUM(AP23:AR23) -> 9959 | U23: =SUM(AS23:AU23) -> 9600 | V23: =SUM(R23:U23) -> 33230 | W23: =V23/V$15 -> 0.035019422 | Z23: =SUM(AZ23:BB23) -> 8100 | AA23: =SUM(BC23:BE23) -> 10500 | AB23: =SUM(BF23:BH23) -> 11700 | AC23: =SUM(BI23:BK23) -> 14550 | AD23: =SUM(Z23:AC23) -> 44850 | AF23: 29434 | AG23: 10167 | AH23: 6575 | AI23: 9120 | AJ23: 1408 | AK23: 97 | AL23: 5593 | AM23: 5783 | AN23: 484 | AO23: 306 | AP23: 2519 | AQ23: 440 | AR23: 7000 | AS23: =AS15*0.03 -> 3600 | AT23: =AT15*0.03 -> 3000 | AU23: =AU15*0.03 -> 3000 | AV23: =SUM(AJ23:AU23) -> 33230 | AW23: =AV23/AV$15 -> 0.035019422 | AX23: 3% of sales | AZ23: =AZ15*0.03 -> 3000 | BA23: =BA15*0.03 -> 2400 | BB23: =BB15*0.03 -> 2700 | BC23: =BC15*0.03 -> 3300 | BD23: =BD15*0.03 -> 3600 | BE23: =BE15*0.03 -> 3600 | BF23: =BF15*0.03 -> 3600 | BG23: =BG15*0.03 -> 3900 | ... BK23: =BK15*0.03 -> 3750 | BL23: =SUM(AZ23:BK23) -> 44850 | BM23: =BL23/BL$15 -> 0.03
B24: Total CGS | C24: =SUM(C17:C23) -> 766923.85 | D24: =C24/C$15 -> 0.59875282 | E24: =SUM(E17:E23) -> 1214036 | F24: =E24/E$15 -> 0.55965571 | G24: =SUM(G17:G23) -> 1468052.7 | H24: =G24/G$15 -> 0.66672179 | I24: =SUM(I17:I23) -> 1311571 | J24: =I24/I$15 -> 0.56498165 | K24: =SUM(K17:K23) -> 415606 | L24: =SUM(L17:L23) -> 263638 | M24: =SUM(M17:M23) -> 309249 | N24: =SUM(N17:N23) -> 250309 | O24: =SUM(O17:O23) -> 1238802 | P24: =O24/O$15 -> 0.70598312 | R24: =SUM(R17:R23) -> 175688 | S24: =SUM(S17:S23) -> 160515 | T24: =SUM(T17:T23) -> 99706 | U24: =SUM(U17:U23) -> 182400 | V24: =SUM(V17:V23) -> 618309 | W24: =V24/V$15 -> 0.6516047 | Z24: =SUM(Z17:Z23) -> 153900 | AA24: =SUM(AA17:AA23) -> 196000 | AB24: =SUM(AB17:AB23) -> 218400 | AC24: =SUM(AC17:AC23) -> 271600 | AD24: =SUM(AD17:AD23) -> 839900 | AF24: =SUM(AF17:AF23) -> 309245 | AG24: =SUM(AG17:AG23) -> 90548 | AH24: =SUM(AH17:AH23) -> 86563 | AI24: =SUM(AI17:AI23) -> 73822 | AJ24: =SUM(AJ17:AJ23) -> 77084 | AK24: =SUM(AK17:AK23) -> 49439 | AL24: =SUM(AL17:AL23) -> 49165 | AM24: =SUM(AM17:AM23) -> 64531 | ... AV24: =SUM(AV17:AV23) -> 618309 | AW24: =AV24/AV$15 -> 0.6516047 | AZ24: =SUM(AZ17:AZ23) -> 57000 | BA24: =SUM(BA17:BA23) -> 45600 | BB24: =SUM(BB17:BB23) -> 51300 | BC24: =SUM(BC17:BC23) -> 61600 | BD24: =SUM(BD17:BD23) -> 67200 | BE24: =SUM(BE17:BE23) -> 67200 | BF24: =SUM(BF17:BF23) -> 67200 | BG24: =SUM(BG17:BG23) -> 72800 | ... BL24: =SUM(BL17:BL23) -> 839900 | BM24: =BL24/BL$15 -> 0.56180602
A25: Gross Margin | C25: =C15-C24 -> 513945.02 | D25: =C25/C$15 -> 0.40124718 | E25: =E15-E24 -> 955219.12 | F25: =E25/E$15 -> 0.44034429 | G25: =G15-G24 -> 733844.3 | H25: =G25/G$15 -> 0.33327821 | I25: =I15-I24 -> 1009869 | J25: =I25/I$15 -> 0.43501835 | K25: =K15-K24 -> 154435 | L25: =L15-L24 -> 141536 | M25: =M15-M24 -> 37894 | N25: =N15-N24 -> 182052 | O25: =O15-O24 -> 515917 | P25: =O25/O$15 -> 0.29401688 | R25: =R15-R24 -> 57267 | S25: =S15-S24 -> 57792 | T25: =T15-T24 -> 77934 | U25: =U15-U24 -> 137600 | V25: =V15-V24 -> 330593 | W25: =V25/V$15 -> 0.3483953 | Z25: =Z15-Z24 -> 116100 | AA25: =AA15-AA24 -> 154000 | AB25: =AB15-AB24 -> 171600 | AC25: =AC15-AC24 -> 213400 | AD25: =AD15-AD24 -> 655100 | AF25: =AF15-AF24 -> 37898 | AG25: =AG15-AG24 -> 65364 | AH25: =AH15-AH24 -> 60821 | AI25: =AI15-AI24 -> 55243 | AJ25: =AJ15-AJ24 -> 20258 | AK25: =AK15-AK24 -> 20267 | AL25: =AL15-AL24 -> 16742 | AM25: =AM15-AM24 -> -5623 | ... AV25: =AV15-AV24 -> 330593 | AW25: =AV25/AV$15 -> 0.3483953 | AZ25: =AZ15-AZ24 -> 43000 | BA25: =BA15-BA24 -> 34400 | BB25: =BB15-BB24 -> 38700 | BC25: =BC15-BC24 -> 48400 | BD25: =BD15-BD24 -> 52800 | BE25: =BE15-BE24 -> 52800 | BF25: =BF15-BF24 -> 52800 | BG25: =BG15-BG24 -> 57200 | ... BL25: =BL15-BL24 -> 655100 | BM25: =BL25/BL$15 -> 0.43819398
K26: =K25/K15 -> 0.27091911 | L26: =L25/L15 -> 0.34932153 | M26: =M25/M15 -> 0.10915963 | N26: =N25/N15 -> 0.4210648 | R26: =R25/R15 -> 0.24582859 | S26: =S25/S15 -> 0.26472811 | T26: =T25/T15 -> 0.43871876 | U26: =U25/U15 -> 0.43 | Z26: =Z25/Z15 -> 0.43 | AA26: =AA25/AA15 -> 0.44 | AB26: =AB25/AB15 -> 0.44 | AC26: =AC25/AC15 -> 0.44 | AF26: =AF25/AF15 -> 0.10917115 | AG26: =AG25/AG15 -> 0.41923649 | AH26: =AH25/AH15 -> 0.4126703 | AI26: =AI25/AI15 -> 0.42802464 | AJ26: =AJ25/AJ15 -> 0.20811161 | AK26: =AK25/AK15 -> 0.29074972 | AL26: =AL25/AL15 -> 0.25402461 | AM26: =AM25/AM15 -> -0.095453928 | ... AU26: =AU25/AU15 -> 0.43 | AX26: hange to 43 | AZ26: =AZ25/AZ15 -> 0.43 | BA26: =BA25/BA15 -> 0.43 | BB26: =BB25/BB15 -> 0.43 | BC26: =BC25/BC15 -> 0.44 | BD26: =BD25/BD15 -> 0.44 | BE26: =BE25/BE15 -> 0.44 | BF26: =BF25/BF15 -> 0.44 | BG26: =BG25/BG15 -> 0.44 | ... BK26: =BK25/BK15 -> 0.44
A27: Selling, General & Administrative
B28: Compensation
B29: Salaries & wages | C29: =QB!F110 -> 0 | D29: =C29/C$15 -> 0 | E29: =QB!K110 -> 216764.24 | F29: =E29/E$15 -> 0.099925655 | G29: =QB!P110 -> 391277.16 | H29: =G29/G$15 -> 0.17770003 | I29: 410305 | J29: =I29/I$15 -> 0.1767459 | K29: 113695 | L29: 113361 | M29: 88012 | N29: 79844 | O29: =SUM(K29:N29) -> 394912 | P29: =O29/O$15 -> 0.22505712 | R29: =SUM(AJ29:AL29) -> 74406 | S29: =SUM(AM29:AO29) -> 40476 | T29: =SUM(AP29:AR29) -> 12500 | U29: =SUM(AS29:AU29) -> 36828 | V29: =SUM(R29:U29) -> 164210 | W29: =V29/V$15 -> 0.17305264 | Z29: =SUM(AZ29:BB29) -> 41828 | AA29: =SUM(BC29:BE29) -> 56424 | AB29: =SUM(BF29:BH29) -> 58722 | AC29: =SUM(BI29:BK29) -> 58722 | AD29: =SUM(Z29:AC29) -> 215696 | AF29: 88012 | AG29: 32685 | AH29: 24892 | AI29: 22267 | AJ29: 29409 | AK29: 22407 | AL29: 22590 | AM29: 17255 | AN29: 14039 | AO29: 9182 | AP29: 5000 | AQ29: 2500 | AR29: 5000 | AS29: =SUM(AS30:AS35) -> 12276 | AT29: =SUM(AT30:AT35) -> 12276 | AU29: =SUM(AU30:AU35) -> 12276 | AV29: =SUM(AJ29:AU29) -> 164210 | AW29: =AV29/AV$15 -> 0.17305264 | AZ29: =SUM(AZ30:AZ35) -> 12276 | BA29: =SUM(BA30:BA35) -> 12276 | BB29: =SUM(BB30:BB35) -> 17276 | BC29: =SUM(BC30:BC35) -> 17276 | BD29: =SUM(BD30:BD35) -> 19574 | BE29: =SUM(BE30:BE35) -> 19574 | BF29: =SUM(BF30:BF35) -> 19574 | BG29: =SUM(BG30:BG35) -> 19574 | ... BK29: =SUM(BK30:BK35) -> 19574 | BL29: =SUM(AZ29:BK29) -> 215696 | BM29: =BL29/BL$15 -> 0.14427826
B30: Spencer | Z30: =SUM(AZ30:BB30) -> 0 | AA30: =SUM(BC30:BE30) -> 0 | AB30: =SUM(BF30:BH30) -> 0 | AC30: =SUM(BI30:BK30) -> 0 | AH30: =$AX30*2 -> 4744 | AI30: =$AX30*2 -> 4744 | AJ30: =$AX30*2 -> 4744 | AK30: 1313 | AX30: 2372
B31: Ryan (Kristopher)/NEW REP | Z31: =SUM(AZ31:BB31) -> 5000 | AA31: =SUM(BC31:BE31) -> 15000 | AB31: =SUM(BF31:BH31) -> 15000 | AC31: =SUM(BI31:BK31) -> 15000 | AH31: =$AX31*2 -> 5000 | AI31: =$AX31*2 -> 5000 | AJ31: =$AX31*2 -> 5000 | AK31: =$AX31*2 -> 5000 | AX31: 2500 | BB31: 5000 | BC31: 5000 | BD31: 5000 | BE31: 5000 | BF31: 5000 | BG31: 5000 | BH31: 5000 | BI31: 5000 | BJ31: 5000 | BK31: 5000
B32: Levi | Z32: =SUM(AZ32:BB32) -> 11328 | AA32: =SUM(BC32:BE32) -> 12924 | AB32: =SUM(BF32:BH32) -> 13722 | AC32: =SUM(BI32:BK32) -> 13722 | AH32: =$AX32*2 -> 4574 | AI32: =$AX32*2 -> 4574 | AJ32: 4416 | AK32: 4468 | AL32: =$AX32*2 -> 4574 | AM32: =$AX32*2 -> 4574 | AN32: =$AX32*2 -> 4574 | AO32: =$AX32*2 -> 4574 | AP32: 3776 | AQ32: 3776 | AR32: 3776 | AS32: 3776 | AT32: 3776 | AU32: 3776 | AX32: 2287 | AZ32: 3776 | BA32: 3776 | BB32: 3776 | BC32: 3776 | BD32: 4574 | BE32: 4574 | BF32: 4574 | BG32: 4574 | BH32: 4574 | BI32: 4574 | BJ32: 4574 | BK32: 4574
B33: McKenna | Z33: =SUM(AZ33:BB33) -> 0 | AA33: =SUM(BC33:BE33) -> 0 | AB33: =SUM(BF33:BH33) -> 0 | AC33: =SUM(BI33:BK33) -> 0 | AH33: =$AX33*2 -> 1834 | AI33: =$AX33*2 -> 1834 | AJ33: 1834 | AK33: 1834 | AX33: 917
B34: Marisa | Z34: =SUM(AZ34:BB34) -> 15000 | AA34: =SUM(BC34:BE34) -> 15000 | AB34: =SUM(BF34:BH34) -> 15000 | AC34: =SUM(BI34:BK34) -> 15000 | AH34: =$AX34*2 -> 2490 | AI34: =$AX34*AI$144 -> 2490 | AJ34: 6666 | AK34: 6667 | AL34: 5000 | AM34: 5000 | AN34: 5000 | AO34: 5000 | AP34: 5000 | AQ34: 5000 | AR34: 5000 | AS34: 5000 | AT34: 5000 | AU34: 5000 | AX34: 1245 | AZ34: 5000 | BA34: 5000 | BB34: 5000 | BC34: 5000 | BD34: 5000 | BE34: 5000 | BF34: 5000 | BG34: 5000 | BH34: 5000 | BI34: 5000 | BJ34: 5000 | BK34: 5000
B35: Jeremiah | Z35: =SUM(AZ35:BB35) -> 10500 | AA35: =SUM(BC35:BE35) -> 13500 | AB35: =SUM(BF35:BH35) -> 15000 | AC35: =SUM(BI35:BK35) -> 15000 | AH35: =$AX35*2 -> 7000 | AI35: =$AX35*2 -> 7000 | AJ35: 3625 | AK35: 0 | AL35: 3000 | AM35: 3000 | AN35: 3000 | AO35: 3500 | AP35: 3500 | AQ35: 3500 | AR35: 3500 | AS35: 3500 | AT35: 3500 | AU35: 3500 | AX35: 3500 | AZ35: 3500 | BA35: 3500 | BB35: 3500 | BC35: 3500 | BD35: 5000 | BE35: 5000 | BF35: 5000 | BG35: 5000 | BH35: 5000 | BI35: 5000 | BJ35: 5000 | BK35: 5000
B36: Contract labor | C36: =QB!F108 -> 142452.45 | D36: =C36/C$15 -> 0.11121548 | E36: =QB!K108 -> 57528.86 | F36: =E36/E$15 -> 0.026520099 | G36: =QB!P108 -> 18232.21 | H36: =G36/G$15 -> 0.0082802283 | I36: 84566 | J36: =I36/I$15 -> 0.036428251 | K36: 30320 | L36: 9582 | M36: 9031 | N36: 16319 | O36: =SUM(K36:N36) -> 65252 | P36: =O36/O$15 -> 0.037186581 | R36: =SUM(AJ36:AL36) -> 18540 | S36: =SUM(AM36:AO36) -> 19428 | T36: =SUM(AP36:AR36) -> 20710 | U36: =SUM(AS36:AU36) -> 17160 | V36: =SUM(R36:U36) -> 75838 | W36: =V36/V$15 -> 0.079921847 | Z36: =SUM(AZ36:BB36) -> 18671 | AA36: =SUM(BC36:BE36) -> 19428 | AB36: =SUM(BF36:BH36) -> 19200 | AC36: =SUM(BI36:BK36) -> 19200 | AD36: =SUM(Z36:AC36) -> 76499 | AF36: 9030 | AG36: 4939 | AH36: 6242 | AI36: 5138 | AJ36: =SUM(AJ37:AJ40) -> 7721 | AK36: =SUM(AK37:AK40) -> 3588 | AL36: 7231 | AM36: 6049 | AN36: 6115 | AO36: 7264 | AP36: 8034 | AQ36: 6695 | AR36: 5981 | AS36: =SUM(AS37:AS40) -> 5720 | AT36: =SUM(AT37:AT40) -> 5720 | AU36: =SUM(AU37:AU40) -> 5720 | AV36: =SUM(AJ36:AU36) -> 75838 | AW36: =AV36/AV$15 -> 0.079921847 | AZ36: =SUM(AZ37:AZ40) -> 5720 | BA36: =SUM(BA37:BA40) -> 5720 | BB36: 7231 | BC36: 6049 | BD36: 6115 | BE36: 7264 | BF36: =SUM(BF37:BF40) -> 6400 | BG36: =SUM(BG37:BG40) -> 6400 | BH36: =SUM(BH37:BH40) -> 6400 | BI36: =SUM(BI37:BI40) -> 6400 | BJ36: =SUM(BJ37:BJ40) -> 6400 | BK36: =SUM(BK37:BK40) -> 6400 | BL36: =SUM(AZ36:BK36) -> 76499 | BM36: =BL36/BL$15 -> 0.0511699
B37: Miguel | Z37: =SUM(AZ37:BB37) -> 8580 | AA37: =SUM(BC37:BE37) -> 9260 | AB37: =SUM(BF37:BH37) -> 9600 | AC37: =SUM(BI37:BK37) -> 9600 | AH37: 2860 | AI37: 2860 | AJ37: 4767 | AK37: 1428 | AL37: 2860 | AM37: 2860 | AN37: 2860 | AO37: 2860 | AP37: 2860 | AQ37: 2860 | AR37: 2860 | AS37: 2860 | AT37: 2860 | AU37: 2860 | AX37: 1430 fulfillment | AZ37: 2860 | BA37: 2860 | BB37: 2860 | BC37: 2860 | BD37: 3200 | BE37: 3200 | BF37: 3200 | BG37: 3200 | BH37: 3200 | BI37: 3200 | BJ37: 3200 | BK37: 3200
B38: Robert | Z38: =SUM(AZ38:BB38) -> 8580 | AA38: =SUM(BC38:BE38) -> 9260 | AB38: =SUM(BF38:BH38) -> 9600 | AC38: =SUM(BI38:BK38) -> 9600 | AH38: 2860 | AI38: 2860 | AJ38: 2954 | AK38: 2160 | AL38: 2860 | AM38: 2860 | AN38: 2860 | AO38: 2860 | AP38: 2860 | AQ38: 2000 | AR38: 2000 | AS38: 2860 | AT38: 2860 | AU38: 2860 | AX38: 1430 sales admin | AZ38: 2860 | BA38: 2860 | BB38: 2860 | BC38: 2860 | BD38: 3200 | BE38: 3200 | BF38: 3200 | BG38: 3200 | BH38: 3200 | BI38: 3200 | BJ38: 3200 | BK38: 3200
Z39: =SUM(AZ39:BB39) -> 0 | AA39: =SUM(BC39:BE39) -> 0 | AB39: =SUM(BF39:BH39) -> 0 | AC39: =SUM(BI39:BK39) -> 0
Z40: =SUM(AZ40:BB40) -> 0 | AA40: =SUM(BC40:BE40) -> 0 | AB40: =SUM(BF40:BH40) -> 0 | AC40: =SUM(BI40:BK40) -> 0
...

Sheet 2024 Budget
A1: Bravado Spice
A2: Forecast 2024 | AD2: 2024 by Month
K3: 2023 Forecast (Original) | R3: 2023 Forecast (Original)
K4: 2023 | R4: 2024 | AD4: Actual | AJ4: Budget
C5: 2019 | E5: 2020 | G5: 2021 | I5: 2022 | K5: Q1 | L5: Q2 | M5: Q3 | N5: Q4 | O5: 2023 | R5: Q1 | S5: Q2 | T5: Q3 | U5: Q4 | V5: 2024 | X5: Notes | Z5: Q3 Actual | AA5: Oct | AB5: Nov | AC5: Dec | AD5: Jan | AE5: Feb | AF5: Mar | AG5: Apr | AH5: May | AI5: June | AJ5: July | AK5: Aug | AL5: Sept | AM5: Oct | AN5: Nov | AO5: Dec | AP5: 2024 Total | AR5: Assumptions
A6: Sales
B7: Retail | AP7: =SUM(AD7:AO7) -> 0 | AQ7: =AP7/AP$15 -> 0
B8: Online/Amazon | AP8: =SUM(AD8:AO8) -> 0 | AQ8: =AP8/AP$15 -> 0
B9: Less Amazon netting | AP9: =SUM(AD9:AO9) -> 0 | AQ9: =AP9/AP$15 -> 0
B10: Distributor | AP10: =SUM(AD10:AO10) -> 0 | AQ10: =AP10/AP$15 -> 0
B11: Franchise | AP11: =SUM(AD11:AO11) -> 0 | AQ11: =AP11/AP$15 -> 0
B12: Total hot sauce | C12: =QB!F20+QB!F30+QB!F33+QB!F34+QB!F40 -> 1176162.1 | E12: =QB!K20+QB!K30+QB!K33+QB!K34+QB!K40 -> 1985300.7 | G12: =QB!P20+QB!P30+QB!P33+QB!P34+QB!P40 -> 1946199.2
B13: Mixers & seasonings | C13: =QB!F24+QB!F29 -> 98761.52 | E13: =QB!K24+QB!K29 -> 182871.54 | G13: =QB!P24+QB!P29 -> 249354.5
B14: Other | C14: =QB!F42+QB!F43+QB!F44 -> 5945.28 | E14: =QB!K42+QB!K43+QB!K44 -> 1082.89 | G14: =QB!P42+QB!P43+QB!P44 -> 6343.26
A15: Sales | C15: =SUM(C12:C14) -> 1280868.9 | D15: =C15/C$15 -> 1 | E15: =SUM(E12:E14) -> 2169255.1 | F15: =E15/E$15 -> 1 | G15: =SUM(G12:G14) -> 2201897 | H15: =G15/G$15 -> 1 | I15: 2321440 | J15: =I15/I$15 -> 1 | K15: 570041 | L15: 405174 | M15: 347143 | N15: 432361 | O15: =SUM(K15:N15) -> 1754719 | P15: =O15/O$15 -> 1 | R15: =SUM(AD15:AF15) -> 232955 | S15: =SUM(AG15:AI15) -> 218307 | T15: =SUM(AJ15:AL15) -> 154911 | U15: =SUM(AM15:AO15) -> 210000 | V15: =SUM(R15:U15) -> 816173 | W15: =V15/V$15 -> 1 | Z15: 347143 | AA15: 155912 | AB15: 147384 | AC15: 129065 | AD15: 97342 | AE15: 69706 | AF15: 65907 | AG15: 58908 | AH15: 77566 | AI15: 81833 | AJ15: 62186 | AK15: 22725 | AL15: 70000 | AM15: 70000 | AN15: 70000 | AO15: 70000 | AP15: =SUM(AD15:AO15) -> 816173 | AQ15: =AP15/AP$15 -> 1 | AR15: Per Jer
A16: Cost of Sales
B17: Co-Packer & ingredients | C17: =QB!F47+QB!F48+QB!F50+QB!F51 -> 497738.93 | D17: =C17/C$15 -> 0.38859476 | E17: 725353 | F17: =E17/E$15 -> 0.33437883 | G17: =QB!P47+QB!P48+QB!P50+QB!P51 -> 943998.9 | H17: =G17/G$15 -> 0.42872073 | I17: 1012654 | J17: =I17/I$15 -> 0.43621804 | K17: 342783 | L17: 213990 | M17: 225540 | N17: 184128 | O17: =SUM(K17:N17) -> 966441 | P17: =O17/O$15 -> 0.55076682 | R17: =SUM(AD17:AF17) -> 101494 | S17: =SUM(AG17:AI17) -> 125769 | T17: =SUM(AJ17:AL17) -> 63046 | U17: =SUM(AM17:AO17) -> 94500 | V17: =SUM(R17:U17) -> 384809 | W17: =V17/V$15 -> 0.4714797 | Z17: 199547 | AA17: 51354 | AB17: 56556 | AC17: 54070 | AD17: 40909 | AE17: 27875 | AF17: 32710 | AG17: 44532 | AH17: 47887 | AI17: 33350 | AJ17: 21398 | AK17: 10148 | AL17: =AL15*0.45 -> 31500 | AM17: =AM15*0.45 -> 31500 | AN17: =AN15*0.45 -> 31500 | AO17: =AO15*0.45 -> 31500 | AP17: =SUM(AD17:AO17) -> 384809 | AQ17: =AP17/AP$15 -> 0.4714797 | AR17: 45% of sales starting June
B18: Shipping & delivery | C18: =QB!F49 -> 115308.88 | D18: =C18/C$15 -> 0.090023954 | E18: =QB!K49 -> 198278.67 | F18: =E18/E$15 -> 0.091404034 | G18: =QB!P49 -> 268052.97 | H18: =G18/G$15 -> 0.12173729 | I18: 214975 | J18: =I18/I$15 -> 0.092604159 | K18: 46962 | L18: 32407 | M18: 27976 | N18: 27158 | O18: =SUM(K18:N18) -> 134503 | P18: =O18/O$15 -> 0.076652159 | R18: =SUM(AD18:AF18) -> 18015 | S18: =SUM(AG18:AI18) -> 12763 | T18: =SUM(AJ18:AL18) -> 12867 | U18: =SUM(AM18:AO18) -> 14700 | V18: =SUM(R18:U18) -> 58345 | W18: =V18/V$15 -> 0.07148607 | Z18: 27976 | AA18: 8573 | AB18: 10446 | AC18: 8139 | AD18: 8646 | AE18: 5159 | AF18: 4210 | AG18: 4062 | AH18: 5030 | AI18: 3671 | AJ18: 4688 | AK18: 3279 | AL18: =0.07*AL15 -> 4900 | AM18: =0.07*AM15 -> 4900 | AN18: =0.07*AN15 -> 4900 | AO18: =0.07*AO15 -> 4900 | AP18: =SUM(AD18:AO18) -> 58345 | AQ18: =AP18/AP$15 -> 0.07148607 | AR18: 7% of sales
B19: Inventory adjustment | I19: -100 | J19: =I19/I$15 -> -4.3076711e-05 | O19: =SUM(K19:N19) -> 0 | R19: =SUM(AD19:AF19) -> 6240 | S19: =SUM(AG19:AI19) -> 3848 | T19: =SUM(AJ19:AL19) -> 2171 | U19: =SUM(AM19:AO19) -> 0 | V19: =SUM(R19:U19) -> 12259 | AD19: 6900 | AE19: -2315 | AF19: 1655 | AG19: 2783 | AH19: 696 | AI19: 369 | AJ19: 1326 | AK19: 845 | AP19: =SUM(AD19:AO19) -> 12259
B20: Materials | C20: =QB!F52 -> 128054.04 | D20: =C20/C$15 -> 0.099974356 | E20: =QB!K52 -> 194413.35 | F20: =E20/E$15 -> 0.089622169 | G20: =QB!P52 -> 179567.31 | H20: =G20/G$15 -> 0.081551185 | J20: =I20/I$15 -> 0 | K20: =SUM(I20:J20) -> 0 | L20: =SUM(I20:K20) -> 0 | M20: =SUM(J20:L20) -> 0 | N20: =SUM(K20:M20) -> 0 | O20: =SUM(K20:N20) -> 0 | P20: =O20/O$15 -> 0 | R20: =SUM(AD20:AF20) -> 0 | S20: =SUM(AG20:AI20) -> 0 | T20: =SUM(AJ20:AL20) -> 0 | U20: =SUM(AM20:AO20) -> 0 | V20: =SUM(R20:U20) -> 0 | W20: =V20/V$15 -> 0 | AP20: =SUM(AD20:AO20) -> 0 | AQ20: =AP20/AP$15 -> 0
B21: KeHe slotting fees | O21: =SUM(K21:N21) -> 0 | R21: =SUM(AD21:AF21) -> 0 | S21: =SUM(AG21:AI21) -> 0 | T21: =SUM(AJ21:AL21) -> 0 | U21: =SUM(AM21:AO21) -> 0 | V21: =SUM(R21:U21) -> 0 | AP21: =SUM(AD21:AO21) -> 0
B22: Swell/other discounts | C22: 25822 | D22: =C22/C$15 -> 0.020159753 | E22: 62660 | F22: =E22/E$15 -> 0.028885491 | I22: 82476 | J22: =I22/I$15 -> 0.035527948 | K22: 18624 | L22: 15910 | M22: 46676 | N22: 34766 | O22: =SUM(K22:N22) -> 115976 | P22: =O22/O$15 -> 0.066093773 | R22: =SUM(AD22:AF22) -> 44790 | S22: =SUM(AG22:AI22) -> 11937 | T22: =SUM(AJ22:AL22) -> 12941 | U22: =SUM(AM22:AO22) -> 12600 | V22: =SUM(R22:U22) -> 82268 | Z22: 52288 | AA22: 20454 | AB22: 12986 | AC22: 2493 | AD22: 19221 | AE22: 18623 | AF22: 6946 | AG22: 7371 | AH22: 2440 | AI22: 2126 | AJ22: 5443 | AK22: 3298 | AL22: =AL15*0.06 -> 4200 | AM22: =AM15*0.06 -> 4200 | AN22: =AN15*0.06 -> 4200 | AO22: =AO15*0.06 -> 4200 | AP22: =SUM(AD22:AO22) -> 82268 | AR22: 8% of sales, bump in June promo, 6% last few mos
B23: Other | D23: =C23/C$15 -> 0 | E23: 33331 | F23: =E23/E$15 -> 0.015365182 | G23: =QB!P53+QB!P54+QB!P55+QB!P56+QB!P57+QB!P58+QB!P59+QB!P60+QB!P61+QB!P62+QB!P64 -> 76433.53 | H23: =G23/G$15 -> 0.034712582 | I23: 1566 | J23: =I23/I$15 -> 0.00067458129 | K23: 7237 | L23: 1331 | M23: 9057 | N23: 4257 | O23: =SUM(K23:N23) -> 21882 | P23: =O23/O$15 -> 0.012470373 | R23: =SUM(AD23:AF23) -> 7098 | S23: =SUM(AG23:AI23) -> 6573 | T23: =SUM(AJ23:AL23) -> 4865 | U23: =SUM(AM23:AO23) -> 6300 | V23: =SUM(R23:U23) -> 24836 | W23: =V23/V$15 -> 0.030429823 | Z23: 29434 | AA23: 10167 | AB23: 6575 | AC23: 9120 | AD23: 1408 | AE23: 97 | AF23: 5593 | AG23: 5783 | AH23: 484 | AI23: 306 | AJ23: 2519 | AK23: 246 | AL23: =AL15*0.03 -> 2100 | AM23: =AM15*0.03 -> 2100 | AN23: =AN15*0.03 -> 2100 | AO23: =AO15*0.03 -> 2100 | AP23: =SUM(AD23:AO23) -> 24836 | AQ23: =AP23/AP$15 -> 0.030429823 | AR23: 3% of sales
B24: Total CGS | C24: =SUM(C17:C23) -> 766923.85 | D24: =C24/C$15 -> 0.59875282 | E24: =SUM(E17:E23) -> 1214036 | F24: =E24/E$15 -> 0.55965571 | G24: =SUM(G17:G23) -> 1468052.7 | H24: =G24/G$15 -> 0.66672179 | I24: =SUM(I17:I23) -> 1311571 | J24: =I24/I$15 -> 0.56498165 | K24: =SUM(K17:K23) -> 415606 | L24: =SUM(L17:L23) -> 263638 | M24: =SUM(M17:M23) -> 309249 | N24: =SUM(N17:N23) -> 250309 | O24: =SUM(O17:O23) -> 1238802 | P24: =O24/O$15 -> 0.70598312 | R24: =SUM(R17:R23) -> 177637 | S24: =SUM(S17:S23) -> 160890 | T24: =SUM(T17:T23) -> 95890 | U24: =SUM(U17:U23) -> 128100 | V24: =SUM(V17:V23) -> 562517 | W24: =V24/V$15 -> 0.68921295 | Z24: =SUM(Z17:Z23) -> 309245 | AA24: =SUM(AA17:AA23) -> 90548 | AB24: =SUM(AB17:AB23) -> 86563 | AC24: =SUM(AC17:AC23) -> 73822 | AD24: =SUM(AD17:AD23) -> 77084 | AE24: =SUM(AE17:AE23) -> 49439 | AF24: =SUM(AF17:AF23) -> 51114 | AG24: =SUM(AG17:AG23) -> 64531 | ... AP24: =SUM(AP17:AP23) -> 562517 | AQ24: =AP24/AP$15 -> 0.68921295
A25: Gross Margin | C25: =C15-C24 -> 513945.02 | D25: =C25/C$15 -> 0.40124718 | E25: =E15-E24 -> 955219.12 | F25: =E25/E$15 -> 0.44034429 | G25: =G15-G24 -> 733844.3 | H25: =G25/G$15 -> 0.33327821 | I25: =I15-I24 -> 1009869 | J25: =I25/I$15 -> 0.43501835 | K25: =K15-K24 -> 154435 | L25: =L15-L24 -> 141536 | M25: =M15-M24 -> 37894 | N25: =N15-N24 -> 182052 | O25: =O15-O24 -> 515917 | P25: =O25/O$15 -> 0.29401688 | R25: =R15-R24 -> 55318 | S25: =S15-S24 -> 57417 | T25: =T15-T24 -> 59021 | U25: =U15-U24 -> 81900 | V25: =V15-V24 -> 253656 | W25: =V25/V$15 -> 0.31078705 | Z25: =Z15-Z24 -> 37898 | AA25: =AA15-AA24 -> 65364 | AB25: =AB15-AB24 -> 60821 | AC25: =AC15-AC24 -> 55243 | AD25: =AD15-AD24 -> 20258 | AE25: =AE15-AE24 -> 20267 | AF25: =AF15-AF24 -> 14793 | AG25: =AG15-AG24 -> -5623 | ... AP25: =AP15-AP24 -> 253656 | AQ25: =AP25/AP$15 -> 0.31078705
K26: =K25/K15 -> 0.27091911 | L26: =L25/L15 -> 0.34932153 | M26: =M25/M15 -> 0.10915963 | N26: =N25/N15 -> 0.4210648 | R26: =R25/R15 -> 0.23746217 | S26: =S25/S15 -> 0.26301035 | T26: =T25/T15 -> 0.38099941 | U26: =U25/U15 -> 0.39 | Z26: =Z25/Z15 -> 0.10917115 | AA26: =AA25/AA15 -> 0.41923649 | AB26: =AB25/AB15 -> 0.4126703 | AC26: =AC25/AC15 -> 0.42802464 | AD26: =AD25/AD15 -> 0.20811161 | AE26: =AE25/AE15 -> 0.29074972 | AF26: =AF25/AF15 -> 0.22445264 | AG26: =AG25/AG15 -> -0.095453928 | ... AO26: =AO25/AO15 -> 0.39
A27: Selling, General & Administrative
B28: Compensation
B29: Salaries & wages | C29: =QB!F110 -> 0 | D29: =C29/C$15 -> 0 | E29: =QB!K110 -> 216764.24 | F29: =E29/E$15 -> 0.099925655 | G29: =QB!P110 -> 391277.16 | H29: =G29/G$15 -> 0.17770003 | I29: 410305 | J29: =I29/I$15 -> 0.1767459 | K29: 113695 | L29: 113361 | M29: 88012 | N29: 79844 | O29: =SUM(K29:N29) -> 394912 | P29: =O29/O$15 -> 0.22505712 | R29: =SUM(AD29:AF29) -> 74406 | S29: =SUM(AG29:AI29) -> 40476 | T29: =SUM(AJ29:AL29) -> 22574 | U29: =SUM(AM29:AO29) -> 45222 | V29: =SUM(R29:U29) -> 182678 | W29: =V29/V$15 -> 0.22382265 | Z29: 88012 | AA29: 32685 | AB29: 24892 | AC29: 22267 | AD29: 29409 | AE29: 22407 | AF29: 22590 | AG29: 17255 | AH29: 14039 | AI29: 9182 | AJ29: 5000 | AK29: 2500 | AL29: 15074 | AM29: 15074 | AN29: 15074 | AO29: 15074 | AP29: =SUM(AD29:AO29) -> 182678 | AQ29: =AP29/AP$15 -> 0.22382265
B30: Spencer | AB30: =$AR30*2 -> 4744 | AC30: =$AR30*2 -> 4744 | AD30: =$AR30*2 -> 4744 | AE30: 1313 | AR30: 2372
B31: Ryan (Kristopher) | AB31: =$AR31*2 -> 5000 | AC31: =$AR31*2 -> 5000 | AD31: =$AR31*2 -> 5000 | AE31: =$AR31*2 -> 5000 | AR31: 2500
B32: Levi | AB32: =$AR32*2 -> 4574 | AC32: =$AR32*2 -> 4574 | AD32: 4416 | AE32: 4468 | AF32: =$AR32*2 -> 4574 | AG32: =$AR32*2 -> 4574 | AH32: =$AR32*2 -> 4574 | AI32: =$AR32*2 -> 4574 | AJ32: 3776 | AK32: 3776 | AL32: 3776 | AM32: 3776 | AN32: 3776 | AO32: 3776 | AR32: 2287
B33: McKenna | AB33: =$AR33*2 -> 1834 | AC33: =$AR33*2 -> 1834 | AD33: 1834 | AE33: 1834 | AR33: 917
B34: Marisa | AB34: =$AR34*2 -> 2490 | AC34: =$AR34*AC$143 -> 2490 | AD34: 6666 | AE34: 6667 | AF34: 5000 | AG34: 5000 | AH34: 5000 | AI34: 5000 | AJ34: 5000 | AK34: 5000 | AL34: 5000 | AM34: 5000 | AN34: 5000 | AO34: 5000 | AR34: 1245
B35: Jeremiah | AB35: =$AR35*2 -> 7000 | AC35: =$AR35*2 -> 7000 | AD35: 3625 | AE35: 0 | AF35: 3000 | AG35: 3000 | AH35: 3000 | AI35: 3500 | AJ35: 3500 | AK35: 3500 | AL35: 3500 | AM35: 3500 | AN35: 3500 | AO35: 3500 | AR35: 3500
B36: Contract labor | C36: =QB!F108 -> 142452.45 | D36: =C36/C$15 -> 0.11121548 | E36: =QB!K108 -> 57528.86 | F36: =E36/E$15 -> 0.026520099 | G36: =QB!P108 -> 18232.21 | H36: =G36/G$15 -> 0.0082802283 | I36: 84566 | J36: =I36/I$15 -> 0.036428251 | K36: 30320 | L36: 9582 | M36: 9031 | N36: 16319 | O36: =SUM(K36:N36) -> 65252 | P36: =O36/O$15 -> 0.037186581 | R36: =SUM(AD36:AF36) -> 18540 | S36: =SUM(AG36:AI36) -> 19428 | T36: =SUM(AJ36:AL36) -> 20449 | U36: =SUM(AM36:AO36) -> 17160 | V36: =SUM(R36:U36) -> 75577 | W36: =V36/V$15 -> 0.092599241 | Z36: 9030 | AA36: 4939 | AB36: 6242 | AC36: 5138 | AD36: =SUM(AD37:AD40) -> 7721 | AE36: =SUM(AE37:AE40) -> 3588 | AF36: 7231 | AG36: 6049 | AH36: 6115 | AI36: 7264 | AJ36: 8034 | AK36: 6695 | AL36: =SUM(AL37:AL40) -> 5720 | AM36: =SUM(AM37:AM40) -> 5720 | AN36: =SUM(AN37:AN40) -> 5720 | AO36: =SUM(AO37:AO40) -> 5720 | AP36: =SUM(AD36:AO36) -> 75577 | AQ36: =AP36/AP$15 -> 0.092599241
B37: Miguel | AB37: 2860 | AC37: 2860 | AD37: 4767 | AE37: 1428 | AF37: 2860 | AG37: 2860 | AH37: 2860 | AI37: 2860 | AJ37: 2860 | AK37: 2860 | AL37: 2860 | AM37: 2860 | AN37: 2860 | AO37: 2860 | AR37: 1430 fulfillment
B38: Robert | AB38: 2860 | AC38: 2860 | AD38: 2954 | AE38: 2160 | AF38: 2860 | AG38: 2860 | AH38: 2860 | AI38: 2860 | AJ38: 2860 | AK38: 2860 | AL38: 2860 | AM38: 2860 | AN38: 2860 | AO38: 2860 | AR38: 1430 sales admin
B41: Payroll taxes | C41: =QB!F109 -> 0 | D41: =C41/C$15 -> 0 | E41: =QB!K109 -> 18516.46 | F41: =E41/E$15 -> 0.0085358608 | G41: =QB!P109 -> 32796.35 | H41: =G41/G$15 -> 0.014894589 | I41: 31028 | J41: =I41/I$15 -> 0.013365842 | K41: 7707 | L41: 6925 | M41: 5184 | N41: 4472 | O41: =SUM(K41:N41) -> 24288 | P41: =O41/O$15 -> 0.013841532 | R41: =SUM(AD41:AF41) -> 4724 | S41: =SUM(AG41:AI41) -> 2011 | T41: =SUM(AJ41:AL41) -> 1555.92 | U41: =SUM(AM41:AO41) -> 3617.76 | V41: =SUM(R41:U41) -> 11908.68 | W41: =V41/V$15 -> 0.014590877 | Z41: 5184 | AA41: 1439 | AB41: 1363 | AC41: 1670 | AD41: 2184 | AE41: 1545 | AF41: 995 | AG41: 683 | AH41: 804 | AI41: 524 | AJ41: 350 | AK41: 0 | AL41: =AL29*0.08 -> 1205.92 | AM41: =AM29*0.08 -> 1205.92 | AN41: =AN29*0.08 -> 1205.92 | AO41: =AO29*0.08 -> 1205.92 | AP41: =SUM(AD41:AO41) -> 11908.68 | AQ41: =AP41/AP$15 -> 0.014590877 | AR41: 8% of payroll
B42: Employee benefits | C42: =QB!F104 -> 6974.56 | D42: =C42/C$15 -> 0.0054451788 | E42: =QB!K104 -> 10175.58 | F42: =E42/E$15 -> 0.0046908175 | G42: =QB!P104 -> 2511.54 | H42: =G42/G$15 -> 0.0011406256 | I42: 18506 | J42: =I42/I$15 -> 0.0079717761 | K42: 3190 | L42: 3417 | M42: 3692 | N42: 4817 | O42: =SUM(K42:N42) -> 15116 | P42: =O42/O$15 -> 0.0086144847 | R42: =SUM(AD42:AF42) -> 690 | S42: =SUM(AG42:AI42) -> 5594 | T42: =SUM(AJ42:AL42) -> 2856 | U42: =SUM(AM42:AO42) -> 1050 | V42: =SUM(R42:U42) -> 10190 | W42: =V42/V$15 -> 0.012485098 | Z42: 3692 | AC42: 4817 | AD42: 345 | AE42: 138 | AF42: 207 | AG42: 3311 | AH42: 138 | AI42: 2145 | AJ42: 1756 | AK42: 0 | AL42: 1100 | AM42: 350 | AN42: 350 | AO42: 350 | AP42: =SUM(AD42:AO42) -> 10190 | AQ42: =AP42/AP$15 -> 0.012485098 | AR42: Actual - Jer & Mar only
...

Sheet 2024 Monthly
A1: Bravado Spice
A2: Budget Worksheet | AE2: Actual
I3: 2022 | P3: 2023 Forecast (Original) | X3: 2024 (Updated 3/11/24)
C4: 2019 | E4: 2020 | G4: 2021 | I4: Q1 | J4: Q2 | K4: Q3 | L4: Q4 Proj | M4: 2022 | O4: Qtr Run Rate | P4: Q1 | Q4: Q2 | R4: Q3 | S4: Q4 | T4: 2023 | V4: Notes | X4: Q1 Actual | Y4: Q2 Actual | Z4: Q3 Actual | AA4: Oct | AB4: Nov | AC4: Dec | AE4: Jan | AF4: Feb | AG4: Mar | AH4: Apr | AI4: May | AJ4: June | AK4: July | AL4: Aug | AM4: Sept | AN4: Oct | AO4: Nov | AP4: Dec | AQ4: 2024 Total | AS4: Assumptions | AT4: Original Notes
A5: Sales
B6: Retail | I6: ='Sales by Segment'!C38 -> 67876.69 | J6: ='Sales by Segment'!E38 -> 65982 | K6: ='Sales by Segment'!G38 -> 55994 | L6: ='Sales by Segment'!K38 -> 40887.67 | M6: =SUM(I6:L6) -> 230740.36 | N6: =M6/M$14 -> 0.099200782 | P6: ='Sales by Segment'!O38 -> 48455.476 | Q6: ='Sales by Segment'!P38 -> 53301.023 | R6: ='Sales by Segment'!Q38 -> 55723.797 | S6: ='Sales by Segment'!R38 -> 84797.082 | T6: ='Sales by Segment'!S38 -> 242277.38 | U6: =T6/T$14 -> 0.077380649 | X6: ='Sales by Segment'!T38 -> 38264 | Y6: 55790 | AQ6: =SUM(AE6:AP6) -> 0 | AR6: =AQ6/AQ$14 -> 0
B7: Online/Amazon | I7: ='Sales by Segment'!C40 -> 108870 | J7: ='Sales by Segment'!E40 -> 94874 | K7: ='Sales by Segment'!G40 -> 100895 | L7: ='Sales by Segment'!K40 -> 132530 | M7: =SUM(I7:L7) -> 437169 | N7: =M7/M$14 -> 0.18794938 | P7: ='Sales by Segment'!O40 -> 120000 | Q7: ='Sales by Segment'!P40 -> 100000 | R7: ='Sales by Segment'!Q40 -> 154000 | S7: ='Sales by Segment'!R40 -> 242000 | T7: ='Sales by Segment'!S40 -> 600000 | U7: =T7/T$14 -> 0.1916332 | X7: ='Sales by Segment'!T40 -> 89837 | Y7: ='Sales by Segment'!U40 -> 78100 | AQ7: =SUM(AE7:AP7) -> 0 | AR7: =AQ7/AQ$14 -> 0
B8: Less Amazon netting | AQ8: =SUM(AE8:AP8) -> 0 | AR8: =AQ8/AQ$14 -> 0
B9: Distributor | I9: ='Sales by Segment'!C22 -> 115641 | J9: ='Sales by Segment'!E22 -> 109617 | K9: ='Sales by Segment'!G22 -> 76149 | L9: ='Sales by Segment'!K22 -> 136365 | M9: =SUM(I9:L9) -> 437772 | N9: =M9/M$14 -> 0.18820862 | P9: ='Sales by Segment'!O22 -> 106256.68 | Q9: ='Sales by Segment'!P22 -> 182882.35 | R9: ='Sales by Segment'!Q22 -> 182445.18 | S9: ='Sales by Segment'!R22 -> 269699.19 | T9: ='Sales by Segment'!S22 -> 741283.4 | U9: =T9/T$14 -> 0.23675752 | X9: ='Sales by Segment'!T22 -> 164797 | Y9: ='Sales by Segment'!U22 -> 124694 | AQ9: =SUM(AE9:AP9) -> 0 | AR9: =AQ9/AQ$14 -> 0
B10: Franchise | I10: ='Sales by Segment'!C35 -> 308016 | J10: ='Sales by Segment'!E35 -> 156713 | K10: ='Sales by Segment'!G35 -> 304392 | L10: ='Sales by Segment'!K35 -> 451191 | M10: =SUM(I10:L10) -> 1220312 | N10: =M10/M$14 -> 0.52464122 | P10: ='Sales by Segment'!O35 -> 332584.14 | Q10: ='Sales by Segment'!P35 -> 293142.55 | R10: ='Sales by Segment'!Q35 -> 388171.76 | S10: ='Sales by Segment'!R35 -> 533522.24 | T10: ='Sales by Segment'!S35 -> 1547420.7 | U10: =T10/T$14 -> 0.49422863 | X10: ='Sales by Segment'!T35 -> 277143 | Y10: ='Sales by Segment'!U35 -> 146688 | AQ10: =SUM(AE10:AP10) -> 0 | AR10: =AQ10/AQ$14 -> 0
B11: Total hot sauce | C11: =QB!F20+QB!F30+QB!F33+QB!F34+QB!F40 -> 1176162.1 | E11: =QB!K20+QB!K30+QB!K33+QB!K34+QB!K40 -> 1985300.7 | G11: =QB!P20+QB!P30+QB!P33+QB!P34+QB!P40 -> 1946199.2
B12: Mixers & seasonings | C12: =QB!F24+QB!F29 -> 98761.52 | E12: =QB!K24+QB!K29 -> 182871.54 | G12: =QB!P24+QB!P29 -> 249354.5
B13: Other | C13: =QB!F42+QB!F43+QB!F44 -> 5945.28 | E13: =QB!K42+QB!K43+QB!K44 -> 1082.89 | G13: =QB!P42+QB!P43+QB!P44 -> 6343.26
B14: Total sales | C14: =SUM(C11:C13) -> 1280868.9 | D14: =C14/C$14 -> 1 | E14: =SUM(E11:E13) -> 2169255.1 | F14: =E14/E$14 -> 1 | G14: =SUM(G11:G13) -> 2201897 | H14: =G14/G$14 -> 1 | I14: =SUM(I6:I10) -> 600403.69 | J14: =SUM(J6:J10) -> 427186 | K14: =SUM(K6:K10) -> 537430 | L14: =SUM(L6:L10) -> 760973.67 | M14: =SUM(M6:M10) -> 2325993.4 | N14: =M14/M$14 -> 1 | O14: =K14 -> 537430 | P14: =SUM(P6:P10) -> 607296.3 | Q14: =SUM(Q6:Q10) -> 629325.93 | R14: =SUM(R6:R10) -> 780340.74 | S14: =SUM(S6:S10) -> 1130018.5 | T14: =SUM(T6:T10) -> 3130981.5 | U14: =T14/T$14 -> 1 | X14: =SUM(X6:X10) -> 570041 | Y14: 405174 | Z14: 347143 | AA14: 155912 | AB14: 147384 | AC14: 129065 | AE14: 104120 | AF14: 82917 | AG14: 100000 | AH14: 200000 | AI14: 200000 | AJ14: 200000 | AK14: 230000 | AL14: 230000 | AM14: 240000 | AN14: 225000 | AO14: 230000 | AP14: 230000 | AQ14: =SUM(AE14:AP14) -> 2272037 | AR14: =AQ14/AQ$14 -> 1 | AS14: TBD
A15: Cost of Sales
B16: Co-Packer & ingredients | C16: =QB!F47+QB!F48+QB!F50+QB!F51 -> 497738.93 | D16: =C16/C$14 -> 0.38859476 | E16: =QB!K47+QB!K48+QB!K50+QB!K51 -> 668009.87 | F16: =E16/E$14 -> 0.30794435 | G16: =QB!P47+QB!P48+QB!P50+QB!P51 -> 943998.9 | H16: =G16/G$14 -> 0.42872073 | I16: =QB!Q47+QB!Q48+QB!Q50+QB!Q51 -> 296571.87 | J16: =QB!R47+QB!R48+QB!R50+QB!R51 -> 170635.73 | K16: =QB!S47+QB!S48+QB!S50+QB!S51 -> 195667.65 | L16: =QB!T47+QB!T48+QB!T50+QB!T51 -> 349942.37 | M16: =SUM(I16:L16) -> 1012817.6 | N16: =M16/M$14 -> 0.43543444 | P16: =(P6*P97)+(P7*P98)+(P9*P99)+(P10*P100) -> 259090.03 | Q16: =(Q6*Q97)+(Q7*Q98)+(Q9*Q99)+(Q10*Q100) -> 273918.04 | R16: =(R6*R97)+(R7*R98)+(R9*R99)+(R10*R100) -> 336007.04 | S16: =(S6*S97)+(S7*S98)+(S9*S99)+(S10*S100) -> 485750.06 | T16: =SUM(P16:S16) -> 1354765.2 | U16: =T16/T$14 -> 0.43269664 | V16: margin assumptions below | X16: 342783 | Y16: 182623 | Z16: 199547 | AA16: 51354 | AB16: 56556 | AC16: 54070 | AE16: 35127 | AF16: 27875 | AG16: =AG14*0.4 -> 40000 | AH16: =AH14*0.4 -> 80000 | AI16: =AI14*0.4 -> 80000 | AJ16: =AJ14*0.4 -> 80000 | AK16: =AK14*0.4 -> 92000 | AL16: =AL14*0.4 -> 92000 | AM16: =AM14*0.4 -> 96000 | AN16: =AN14*0.4 -> 90000 | ... AP16: =AP14*0.4 -> 92000 | AQ16: =SUM(AE16:AP16) -> 897002 | AR16: =AQ16/AQ$14 -> 0.39480079 | AS16: 40% of sales
B17: Shipping & delivery | C17: =QB!F49 -> 115308.88 | D17: =C17/C$14 -> 0.090023954 | E17: =QB!K49 -> 198278.67 | F17: =E17/E$14 -> 0.091404034 | G17: =QB!P49 -> 268052.97 | H17: =G17/G$14 -> 0.12173729 | I17: =QB!Q49 -> 51915.66 | J17: =QB!R49 -> 50350.69 | K17: =QB!S49 -> 44278.39 | L17: =QB!T49 -> 68459.79 | M17: =SUM(I17:L17) -> 215004.53 | N17: =M17/M$14 -> 0.092435573 | P17: =P14*0.09 -> 54656.667 | Q17: =Q14*0.09 -> 56639.333 | R17: =R14*0.09 -> 70230.667 | S17: =S14*0.09 -> 101701.67 | T17: =SUM(P17:S17) -> 283228.33 | U17: =T17/T$14 -> 0.09045992 | V17: 9% of sales | X17: 46962 | Y17: 32407 | Z17: 27976 | AA17: 8573 | AB17: 10446 | AC17: 8139 | AE17: 8646 | AF17: 5159 | AG17: =0.07*AG14 -> 7000 | AH17: =0.07*AH14 -> 14000 | AI17: =0.07*AI14 -> 14000 | AJ17: =0.07*AJ14 -> 14000 | AK17: =0.07*AK14 -> 16100 | AL17: =0.07*AL14 -> 16100 | AM17: =0.07*AM14 -> 16800 | AN17: =0.07*AN14 -> 15750 | ... AP17: =0.07*AP14 -> 16100 | AQ17: =SUM(AE17:AP17) -> 159755 | AR17: =AQ17/AQ$14 -> 0.070313556 | AS17: 7% of sales
B18: Inventory adjustment | AE18: 6900 | AF18: -2315 | AQ18: =SUM(AE18:AP18) -> 4585
B19: Materials | C19: =QB!F52 -> 128054.04 | D19: =C19/C$14 -> 0.099974356 | E19: =QB!K52 -> 194413.35 | F19: =E19/E$14 -> 0.089622169 | G19: =QB!P52 -> 179567.31 | H19: =G19/G$14 -> 0.081551185 | I19: =QB!Q52 -> 0 | J19: =QB!R52 -> 0 | K19: =QB!S52 -> 0 | L19: =QB!T52 -> 0 | M19: =SUM(I19:L19) -> 0 | N19: =M19/M$14 -> 0 | P19: =SUM(L19:O19) -> 0 | Q19: =SUM(M19:P19) -> 0 | R19: =SUM(N19:Q19) -> 0 | S19: =SUM(O19:R19) -> 0 | T19: =SUM(P19:S19) -> 0 | U19: =T19/T$14 -> 0 | X19: =SUM(T19:V19) -> 0 | AQ19: =SUM(AE19:AP19) -> 0 | AR19: =AQ19/AQ$14 -> 0
B20: KeHe slotting fees | AQ20: =SUM(AE20:AP20) -> 0
A21: ? | B21: Swell/other discounts | X21: 25860 | Y21: 17408 | Z21: 52288 | AA21: 20454 | AB21: 12986 | AC21: 2493 | AE21: 17155 | AF21: 16557 | AG21: =AG14*0.08 -> 8000 | AH21: =AH14*0.08 -> 16000 | AI21: =AI14*0.08 -> 16000 | AJ21: =AJ14*0.08 -> 16000 | AK21: =AK14*0.08 -> 18400 | AL21: =AL14*0.08 -> 18400 | AM21: =AM14*0.08 -> 19200 | AN21: =AN14*0.08 -> 18000 | ... AP21: =AP14*0.08 -> 18400 | AQ21: =SUM(AE21:AP21) -> 200512 | AS21: 8% of sales
A22: ? | B22: Other | C22: =QB!F53+QB!F54+QB!F55+QB!F56+QB!F57+QB!F58+QB!F59+QB!F60+QB!F61+QB!F62+QB!F64 -> 25822.27 | D22: =C22/C$14 -> 0.020159964 | E22: =QB!K53+QB!K54+QB!K55+QB!K56+QB!K57+QB!K58+QB!K59+QB!K60+QB!K61+QB!K62+QB!K64 -> 154060.7 | F22: =E22/E$14 -> 0.071020092 | G22: =QB!P53+QB!P54+QB!P55+QB!P56+QB!P57+QB!P58+QB!P59+QB!P60+QB!P61+QB!P62+QB!P64 -> 76433.53 | H22: =G22/G$14 -> 0.034712582 | I22: =QB!Q53+QB!Q54+QB!Q55+QB!Q56+QB!Q57+QB!Q58+QB!Q59+QB!Q60+QB!Q61+QB!Q62+QB!Q64 -> 15108.43 | J22: =QB!R53+QB!R54+QB!R55+QB!R56+QB!R57+QB!R58+QB!R59+QB!R60+QB!R61+QB!R62+QB!R64 -> 25808.14 | K22: =QB!S53+QB!S54+QB!S55+QB!S56+QB!S57+QB!S58+QB!S59+QB!S60+QB!S61+QB!S62+QB!S64 -> 15454.42 | L22: =QB!T53+QB!T54+QB!T55+QB!T56+QB!T57+QB!T58+QB!T59+QB!T60+QB!T61+QB!T62+QB!T64 -> 27571.25 | M22: =SUM(I22:L22) -> 83942.24 | N22: =M22/M$14 -> 0.03608877 | P22: =P14*0.03 -> 18218.889 | Q22: =Q14*0.03 -> 18879.778 | R22: =R14*0.03 -> 23410.222 | S22: =S14*0.03 -> 33900.556 | T22: =SUM(P22:S22) -> 94409.444 | U22: =T22/T$14 -> 0.030153307 | V22: 3% of sales | Y22: 31200 | Z22: 29434 | AA22: 10167 | AB22: 6575 | AC22: 9120 | AE22: 1408 | AF22: 281 | AG22: =AG14*0.02 -> 2000 | AH22: =AH14*0.02 -> 4000 | AI22: =AI14*0.02 -> 4000 | AJ22: =AJ14*0.02 -> 4000 | AK22: =AK14*0.02 -> 4600 | AL22: =AL14*0.02 -> 4600 | AM22: =AM14*0.02 -> 4800 | AN22: =AN14*0.02 -> 4500 | ... AP22: =AP14*0.02 -> 4600 | AQ22: =SUM(AE22:AP22) -> 43389 | AR22: =AQ22/AQ$14 -> 0.01909696 | AS22: 2% of sales
B23: Total CGS | C23: =SUM(C16:C22) -> 766924.12 | D23: =C23/C$14 -> 0.59875303 | E23: =SUM(E16:E22) -> 1214762.6 | F23: =E23/E$14 -> 0.55999065 | G23: =SUM(G16:G22) -> 1468052.7 | H23: =G23/G$14 -> 0.66672179 | I23: =SUM(I16:I22) -> 363595.96 | J23: =SUM(J16:J22) -> 246794.56 | K23: =SUM(K16:K22) -> 255400.46 | L23: =SUM(L16:L22) -> 445973.41 | M23: =SUM(M16:M22) -> 1311764.4 | N23: =M23/M$14 -> 0.56395879 | O23: =K23 -> 255400.46 | P23: =SUM(P16:P22) -> 331965.59 | Q23: =SUM(Q16:Q22) -> 349437.15 | R23: =SUM(R16:R22) -> 429647.93 | S23: =SUM(S16:S22) -> 621352.28 | T23: =SUM(T16:T22) -> 1732402.9 | U23: =T23/T$14 -> 0.55330987 | X23: =SUM(X16:X22) -> 415605 | Y23: =SUM(Y16:Y22) -> 263638 | Z23: =SUM(Z16:Z22) -> 309245 | AA23: =SUM(AA16:AA22) -> 90548 | AB23: =SUM(AB16:AB22) -> 86563 | AC23: =SUM(AC16:AC22) -> 73822 | AE23: =SUM(AE16:AE22) -> 69236 | AF23: =SUM(AF16:AF22) -> 47557 | AG23: =SUM(AG16:AG22) -> 57000 | AH23: =SUM(AH16:AH22) -> 114000 | AI23: =SUM(AI16:AI22) -> 114000 | AJ23: =SUM(AJ16:AJ22) -> 114000 | AK23: =SUM(AK16:AK22) -> 131100 | AL23: =SUM(AL16:AL22) -> 131100 | ... AQ23: =SUM(AQ16:AQ22) -> 1305243 | AR23: =AQ23/AQ$14 -> 0.5744814
A24: Gross Margin | C24: =C14-C23 -> 513944.75 | D24: =C24/C$14 -> 0.40124697 | E24: =E14-E23 -> 954492.55 | F24: =E24/E$14 -> 0.44000935 | G24: =G14-G23 -> 733844.3 | H24: =G24/G$14 -> 0.33327821 | I24: =I14-I23 -> 236807.73 | J24: =J14-J23 -> 180391.44 | K24: =K14-K23 -> 282029.54 | L24: =L14-L23 -> 315000.26 | M24: =M14-M23 -> 1014229 | N24: =M24/M$14 -> 0.43604121 | O24: =O14*0.41 -> 220346.3 | P24: =P14-P23 -> 275330.71 | Q24: =Q14-Q23 -> 279888.78 | R24: =R14-R23 -> 350692.81 | S24: =S14-S23 -> 508666.24 | T24: =T14-T23 -> 1398578.5 | U24: =T24/T$14 -> 0.44669013 | X24: =X14-X23 -> 154436 | Y24: =Y14-Y23 -> 141536 | Z24: =Z14-Z23 -> 37898 | AA24: =AA14-AA23 -> 65364 | AB24: =AB14-AB23 -> 60821 | AC24: =AC14-AC23 -> 55243 | AE24: =AE14-AE23 -> 34884 | AF24: =AF14-AF23 -> 35360 | AG24: =AG14-AG23 -> 43000 | AH24: =AH14-AH23 -> 86000 | AI24: =AI14-AI23 -> 86000 | AJ24: =AJ14-AJ23 -> 86000 | AK24: =AK14-AK23 -> 98900 | AL24: =AL14-AL23 -> 98900 | ... AQ24: =AQ14-AQ23 -> 966794 | AR24: =AQ24/AQ$14 -> 0.4255186
